<?xml version="1.0" ?>
<!-- =================================================================================== -->
<!-- |    This document was autogenerated by xacro from myrobot.xacro                  | -->
<!-- |    EDITING THIS FILE BY HAND IS NOT RECOMMENDED                                 | -->
<!-- =================================================================================== -->
<robot name="myrobot" xmlns:xacro="http://www.ros.org/wiki/xacro">
  <!-- small - inertia of imaginary links that were needed to create ball joint - undefined value
				smaller value - acts as a spring,  bigger value- to stiff -->
  <!-- friction, damping, values that affect the joint, too big damping is absorbs too much kinetic energy while to small damping 
		results as... I must determine middle value and than tweak every parametar and observe what happes with the system -->
  <!-- MACRO ARGUMETS EXPLANATION-->
  <!-- width - 2*width is the width of the first rigid link (base of the rope, hook) -->
  <!-- width_1 - 2*width_1 is the width of the every other rigif link (series of connected rigid links with ball joints represents a rope-->
  <!-- body_len - length of the link (cylinder with radius = width_1 and length=body_len-->
  <!-- box param - length of the edge of the box that represents base link to which rope is attached-->
  <!-- spawn_point = z value in relation to the origin of the world for base link-->
  <!-- radius = radius of the load that is represented as a sphere-->
  <!-- small = very small value that is needed for inertia element of every infintensimaly small link -->
  <!-- load_mass = mass of the load that is carried by rope-->
  <!-- rope_mass = mass of the links that create rope, in order to generate inertia (1/12*mass*height)+1/4*mass*radius^2)-->
  <!-- REFERENCE FRAME/CHILD/PARENT http://wiki.ros.org/urdf/XML/joint/-->
  <!-- SDF documentation: http://sdformat.org/ -->
  <!-- xacro(XML macro): http://wiki.ros.org/xacro -->
  <!-- URDF in GAZEBO: http://gazebosim.org/tutorials/?tut=ros_urdf#%3Cgazebo%3Eelementforthetag -->
  <!-- URDF tutorials:http://wiki.ros.org/urdf/Tutorials -->
  <!-- Gravity disable: http://answers.gazebosim.org/question/13416/how-to-disable-gravity-only-for-a-specific-model-in-gazebo/ -->
  <!-- WORLD_TO_BASE fixed joint - TF between base and world -->
  <!-- NEXT_STEPS NEXT_STEPS NEXT_STEPS -->
  <!-- BASE_TO_ROPE1 link is ofsetted for -box_param/2 so it could be connected on bottom of the base, while visual properties
			of link rope_1 are offseted by -body_len/2 so we could connect it on the bottom of  the base and have full link at disposal-->
  <!-- CREATE BALL LINK - series of revolute joints or infitensimaly small links connected with simple revolute/revolute joints-->
  <!-- PHYSICS THE ROPE, INERTIA ELEMENTS FOR ROPE AND LOAD SHOULD BE CALCULATED, DONE -->
  <!-- STANDARD UNITS OF MEASURE AND COORDINATE CONVENTION : http://www.ros.org/reps/rep->13.html -->
  <!-- XACRO PROPERTIES, LAUNCH FILE AUTOMATICALLY CONVERTS XACRO TO URDF -->
  <!-- DIFFERENT LOAD, DIFFERENT INERTIA ELEMENT, FUNCTION THAT CREATES LOAD DEPENDENT ON ITS SHAPE-->
  <link name="world"/>
  <link name="base_link">
    <visual>
      <geometry>
        <box size="0.5 1.5 0.5"/>
      </geometry>
    </visual>
    <collision>
      <geometry>
        <box size="0.5 1.5 0.5"/>
      </geometry>
    </collision>
    <inertial>
      <mass value="0.005"/>
      <inertia ixx="0.005" ixy="0.0" ixz="0.0" iyy="0.005" iyz="0.0" izz="0.005"/>
    </inertial>
  </link>
  <link name="leg1">
    <visual>
      <geometry>
        <box size="0.5 0.25 3"/>
      </geometry>
      <origin rpy="0 0 0" xyz="0 0 -1.5"/>
    </visual>
    <collision>
      <geometry>
        <box size="0.5 0.25 3"/>
      </geometry>
      <origin rpy="0 0 0" xyz="0 0 -1.5"/>
    </collision>
    <inertial>
      <mass value="100"/>
      <inertia ixx="100" ixy="0.0" ixz="0.0" iyy="100" iyz="0.0" izz="100"/>
    </inertial>
  </link>
  <link name="leg2">
    <visual>
      <geometry>
        <box size="0.5 0.25 3"/>
      </geometry>
      <origin rpy="0 0 0" xyz="0 0 -1.5"/>
    </visual>
    <collision>
      <geometry>
        <box size="0.5 0.25 3"/>
      </geometry>
      <origin rpy="0 0 0" xyz="0 0 -1.5"/>
    </collision>
    <inertial>
      <mass value="100"/>
      <inertia ixx="100" ixy="0.0" ixz="0.0" iyy="100" iyz="0.0" izz="100"/>
    </inertial>
  </link>
  <link name="rope_1">
    <visual>
      <geometry>
        <cylinder length="0.2" radius="0.01"/>
      </geometry>
      <origin rpy="0 0 0" xyz="0 0 -0.1"/>
    </visual>
    <collision>
      <geometry>
        <cylinder length="0.2" radius="0.01"/>
      </geometry>
      <origin rpy="0 0 0" xyz="0  0 -0.1"/>
    </collision>
    <inertial>
      <mass value="0.1"/>
      <inertia ixx="0.1" ixy="0.0" ixz="0.0" iyy="0.1" iyz="0.0" izz="0.1"/>
      <origin rpy="0 0 0" xyz="0 0 -0.1"/>
    </inertial>
  </link>
  <link name="rope_2">
    <visual>
      <geometry>
        <cylinder length="0.2" radius="0.01"/>
      </geometry>
      <origin rpy="0 0 0" xyz="0 0 -0.1"/>
    </visual>
    <collision>
      <geometry>
        <cylinder length="0.2" radius="0.01"/>
      </geometry>
      <origin rpy="0 0 0" xyz="0 0 -0.1"/>
    </collision>
    <inertial>
      <mass value="0.1"/>
      <inertia ixx="0.1" ixy="0.0" ixz="0.0" iyy="0.1" iyz="0.0" izz="0.1"/>
      <origin rpy="0 0 0" xyz="0 0 -0.1"/>
    </inertial>
  </link>
  <link name="rope_3">
    <visual>
      <geometry>
        <cylinder length="0.2" radius="0.01"/>
      </geometry>
      <origin rpy="0 0 0" xyz="0 0 -0.1"/>
    </visual>
    <collision>
      <geometry>
        <cylinder length="0.2" radius="0.01"/>
      </geometry>
      <origin rpy="0 0 0" xyz="0 0 -0.1"/>
    </collision>
    <inertial>
      <mass value="0.1"/>
      <inertia ixx="0.1" ixy="0.1" ixz="0.1" iyy="0.1" iyz="0.0" izz="0.1"/>
      <origin rpy="0 0 0" xyz="0 0 -0.1"/>
    </inertial>
  </link>
  <link name="rope_4">
    <visual>
      <geometry>
        <cylinder length="0.2" radius="0.01"/>
      </geometry>
      <origin rpy="0 0 0" xyz="0 0 -0.1"/>
    </visual>
    <collision>
      <geometry>
        <cylinder length="0.2" radius="0.01"/>
      </geometry>
      <origin rpy="0 0 0" xyz="0 0 -0.1"/>
    </collision>
    <inertial>
      <mass value="0.1"/>
      <inertia ixx="0.1" ixy="0.0" ixz="0.0" iyy="0.1" iyz="0.0" izz="0.1"/>
      <origin rpy="0 0 0" xyz="0 0 -0.1"/>
    </inertial>
  </link>
  <link name="rope_5">
    <visual>
      <geometry>
        <cylinder length="0.2" radius="0.01"/>
      </geometry>
      <origin rpy="0 0 0" xyz="0 0 -0.1"/>
    </visual>
    <collision>
      <geometry>
        <cylinder length="0.2" radius="0.01"/>
      </geometry>
      <origin rpy="0 0 0" xyz="0 0 -0.1"/>
    </collision>
    <inertial>
      <mass value="0.1"/>
      <inertia ixx="0.1" ixy="0.0" ixz="0.0" iyy="0.1" iyz="0.0" izz="0.1"/>
      <origin rpy="0 0 0" xyz="0 0 -0.1"/>
    </inertial>
  </link>
  <link name="rope_6">
    <visual>
      <geometry>
        <cylinder length="0.2" radius="0.01"/>
      </geometry>
      <origin rpy="0 0 0" xyz="0 0 -0.1"/>
    </visual>
    <collision>
      <geometry>
        <cylinder length="0.2" radius="0.01"/>
      </geometry>
      <origin rpy="0 0 0" xyz="0 0 -0.1"/>
    </collision>
    <inertial>
      <mass value="0.1"/>
      <inertia ixx="0.1" ixy="0.0" ixz="0.0" iyy="0.1" iyz="0.0" izz="0.1"/>
      <origin rpy="0 0 0" xyz="0 0 -0.1"/>
    </inertial>
  </link>
  <link name="rope_7">
    <visual>
      <geometry>
        <cylinder length="0.2" radius="0.01"/>
      </geometry>
      <origin rpy="0 0 0" xyz="0 0 -0.1"/>
    </visual>
    <collision>
      <geometry>
        <cylinder length="0.2" radius="0.01"/>
      </geometry>
      <origin rpy="0 0 0" xyz="0 0 -0.1"/>
    </collision>
    <inertial>
      <mass value="0.1"/>
      <inertia ixx="0.1" ixy="0.0" ixz="0.0" iyy="0.1" iyz="0.0" izz="0.1"/>
      <origin rpy="0 0 0" xyz="0 0 -0.1"/>
    </inertial>
  </link>
  <link name="load">
    <visual>
      <geometry>
        <sphere radius="0.1"/>
      </geometry>
      <origin rpy="0 0 0" xyz="0 0 -0.1"/>
    </visual>
    <collision>
      <geometry>
        <sphere radius="0.1"/>
      </geometry>
      <origin rpy="0 0 0" xyz="0 0 -0.1"/>
    </collision>
    <inertial>
      <mass value="2"/>
      <inertia ixx="0.008" ixy="0.0" ixz="0.0" iyy="0.008" iyz="0.0" izz="0.008"/>
      <origin rpy="0 0 0" xyz="0 0 -0.1"/>
    </inertial>
  </link>
  <joint name="world_to_base_link" type="fixed">
    <parent link="world"/>
    <child link="base_link"/>
    <origin xyz="0 0 3"/>
  </joint>
  <joint name="leg1_base_link" type="fixed">
    <parent link="base_link"/>
    <child link="leg1"/>
    <origin xyz="0 0.875 0"/>
  </joint>
  <joint name="leg2_base_link" type="fixed">
    <parent link="base_link"/>
    <child link="leg2"/>
    <origin xyz="0 -0.875 0"/>
  </joint>
  <joint name="baselink_to_rope1Psi" type="revolute">
    <parent link="base_link"/>
    <child link="rope_1Psi_link"/>
    <origin xyz="0 0 -0.25"/>
    <axis xyz="0 0 1"/>
    <dynamics damping="0.05" friction="0.05"/>
    <limit effort="1000" lower="-0.196349540849" upper="0.196349540849" velocity="300"/>
  </joint>
  <link name="rope_1Psi_link">
    <inertial>
      <mass value="0.1"/>
      <inertia ixx="0.1" ixy="0.0" ixz="0.0" iyy="0.1" iyz="0.0" izz="0.1"/>
    </inertial>
  </link>
  <joint name="rope1Psi_to_rope1Theta" type="revolute">
    <parent link="rope_1Psi_link"/>
    <child link="rope_1Theta_link"/>
    <axis xyz="0 1 0"/>
    <dynamics damping="0.05" friction="0.05"/>
    <limit effort="1000" lower="-1.57079632679" upper="1.57079632679" velocity="300"/>
  </joint>
  <link name="rope_1Theta_link">
    <inertial>
      <mass value="0.1"/>
      <inertia ixx="0.1" ixy="0.0" ixz="0.0" iyy="0.1" iyz="0.0" izz="0.1"/>
    </inertial>
  </link>
  <joint name="rope1Theta_to_rope1" type="revolute">
    <parent link="rope_1Theta_link"/>
    <child link="rope_1"/>
    <axis xyz="1 0 0"/>
    <dynamics damping="0.05" friction="0.05"/>
    <limit effort="1000" lower="-1.57079632679" upper="1.57079632679" velocity="300"/>
  </joint>
  <!--<joint name="base_linktorope1" type="revolute">
    		<parent link="base_link"/>
    		<child link="rope_1"/>
    		<origin xyz="0 0 ${-box_param/2}"/>
			<axis xyz="0 1 0"/>
			<limit lower="${-pi/2}" upper="${pi/2}" effort="0.01" velocity="0.01"/>
		</joint>-->
  <joint name="rope1_to_rope2Psi" type="revolute">
    <parent link="rope_1"/>
    <child link="rope_2Psi_link"/>
    <origin xyz="0 0 -0.2"/>
    <axis xyz="0 0 1"/>
    <dynamics damping="0.05" friction="0.05"/>
    <limit effort="1000" lower="-0.196349540849" upper="0.196349540849" velocity="300"/>
  </joint>
  <link name="rope_2Psi_link">
    <inertial>
      <mass value="0.1"/>
      <inertia ixx="0.1" ixy="0.0" ixz="0.0" iyy="0.1" iyz="0.0" izz="0.1"/>
    </inertial>
  </link>
  <joint name="rope2Psi_to_rope2Theta" type="revolute">
    <parent link="rope_2Psi_link"/>
    <child link="rope_2Theta_link"/>
    <axis xyz="0 1 0"/>
    <dynamics damping="0.05" friction="0.05"/>
    <limit effort="1000" lower="-1.57079632679" upper="1.57079632679" velocity="300"/>
  </joint>
  <link name="rope_2Theta_link">
    <inertial>
      <mass value="0.1"/>
      <inertia ixx="0.1" ixy="0.0" ixz="0.0" iyy="0.1" iyz="0.0" izz="0.1"/>
    </inertial>
  </link>
  <joint name="rope2Theta_to_rope2" type="revolute">
    <parent link="rope_2Theta_link"/>
    <child link="rope_2"/>
    <axis xyz="1 0 0"/>
    <dynamics damping="0.05" friction="0.05"/>
    <limit effort="1000" lower="-1.57079632679" upper="1.57079632679" velocity="300"/>
  </joint>
  <!--<joint name="rope1_to_rope2" type="revolute">
			<parent link="rope_1"/>
			<child link="rope_2"/>
			<origin xyz="0 0 ${-body_len}"/>
			<axis xyz="0 1 0" />
			<limit lower="${-pi/2}" upper="${pi/2}" effort="0.01" velocity="0.01"/>
		</joint>-->
  <joint name="rope2_to_rope3Psi" type="revolute">
    <parent link="rope_2"/>
    <child link="rope_3Psi_link"/>
    <origin xyz="0 0 -0.2"/>
    <axis xyz="0 0 1"/>
    <dynamics damping="0.05" friction="0.05"/>
    <limit effort="1000" lower="-0.196349540849" upper="0.196349540849" velocity="300"/>
  </joint>
  <link name="rope_3Psi_link">
    <inertial>
      <mass value="0.1"/>
      <inertia ixx="0.1" ixy="0.0" ixz="0.0" iyy="0.1" iyz="0.0" izz="0.1"/>
    </inertial>
  </link>
  <joint name="rope3Psi_to_rope3Theta" type="revolute">
    <parent link="rope_3Psi_link"/>
    <child link="rope_3Theta_link"/>
    <axis xyz="0 1 0"/>
    <dynamics damping="0.05" friction="0.05"/>
    <limit effort="1000" lower="-1.57079632679" upper="1.57079632679" velocity="300"/>
  </joint>
  <link name="rope_3Theta_link">
    <inertial>
      <mass value="0.1"/>
      <inertia ixx="0.1" ixy="0.0" ixz="0.0" iyy="0.1" iyz="0.0" izz="0.1"/>
    </inertial>
  </link>
  <joint name="rope3Theta_to_rope3" type="revolute">
    <parent link="rope_3Theta_link"/>
    <child link="rope_3"/>
    <axis xyz="1 0 0"/>
    <dynamics damping="0.05" friction="0.05"/>
    <limit effort="1000" lower="-1.57079632679" upper="1.57079632679" velocity="300"/>
  </joint>
  <!--<joint name="rope2_to_rope3" type="revolute">
			<parent link="rope_2"/>
			<child link="rope_3"/>
			<origin xyz="0 0 ${-body_len}"/>
			<axis xyz="1 0 0"/>
			<limit lower="${-pi/2}" upper="${pi/2}" effort="0.01" velocity="0.01"/>
		</joint>-->
  <!--<joint name="rope3_to_rope4" type="revolute">
			<parent link="rope_3"/>
			<child link="rope_4"/>
			<origin xyz="0 0 ${-body_len}"/>
			<limit lower="${-pi/2}" upper="${pi/2}" effort="0.01" velocity="0.01"/>
		</joint>-->
  <!-- for starters ball joint is represented as series of revolute joints -->
  <!-- doesn't work in GAZEBO, possible problem could be lack of inertial elements for imaginary links-->
  <joint name="rope3_to_rope4Psi" type="revolute">
    <parent link="rope_3"/>
    <child link="rope_4Psi_link"/>
    <origin xyz="0 0 -0.2"/>
    <axis xyz="0 0 1"/>
    <dynamics damping="0.05" friction="0.05"/>
    <limit effort="1000" lower="-0.196349540849" upper="0.196349540849" velocity="300"/>
  </joint>
  <link name="rope_4Psi_link">
    <inertial>
      <mass value="0.1"/>
      <inertia ixx="0.1" ixy="0.0" ixz="0.0" iyy="0.1" iyz="0.0" izz="0.1"/>
    </inertial>
  </link>
  <joint name="rope4Psi_to_rope4Theta" type="revolute">
    <parent link="rope_4Psi_link"/>
    <child link="rope_4Theta_link"/>
    <axis xyz="0 1 0"/>
    <dynamics damping="0.05" friction="0.05"/>
    <limit effort="1000" lower="-1.57079632679" upper="1.57079632679" velocity="300"/>
  </joint>
  <link name="rope_4Theta_link">
    <inertial>
      <mass value="0.1"/>
      <inertia ixx="0.1" ixy="0.0" ixz="0.0" iyy="0.1" iyz="0.0" izz="0.1"/>
    </inertial>
  </link>
  <joint name="rope4Theta_to_rope4" type="revolute">
    <parent link="rope_4Theta_link"/>
    <child link="rope_4"/>
    <axis xyz="1 0 0"/>
    <dynamics damping="0.05" friction="0.05"/>
    <limit effort="1000" lower="-1.57079632679" upper="1.57079632679" velocity="300"/>
  </joint>
  <joint name="rope4_to_rope5Psi" type="revolute">
    <parent link="rope_4"/>
    <child link="rope_5Psi_link"/>
    <origin xyz="0 0 -0.2"/>
    <axis xyz="0 0 1"/>
    <dynamics damping="0.05" friction="0.05"/>
    <limit effort="1000" lower="-0.196349540849" upper="0.196349540849" velocity="300"/>
  </joint>
  <link name="rope_5Psi_link">
    <inertial>
      <mass value="0.1"/>
      <inertia ixx="0.1" ixy="0.0" ixz="0.0" iyy="0.1" iyz="0.0" izz="0.1"/>
    </inertial>
  </link>
  <joint name="rope5Psi_to_rope5Theta" type="revolute">
    <parent link="rope_5Psi_link"/>
    <child link="rope_5Theta_link"/>
    <axis xyz="0 1 0"/>
    <dynamics damping="0.05" friction="0.05"/>
    <limit effort="1000" lower="-1.57079632679" upper="1.57079632679" velocity="300"/>
  </joint>
  <link name="rope_5Theta_link">
    <inertial>
      <mass value="0.1"/>
      <inertia ixx="0.1" ixy="0.0" ixz="0.0" iyy="0.1" iyz="0.0" izz="0.1"/>
    </inertial>
  </link>
  <joint name="rope5Theta_to_rope5" type="revolute">
    <parent link="rope_5Theta_link"/>
    <child link="rope_5"/>
    <axis xyz="1 0 0"/>
    <dynamics damping="0.05" friction="0.05"/>
    <limit effort="1000" lower="-1.57079632679" upper="1.57079632679" velocity="300"/>
  </joint>
  <joint name="rope5_to_rope6Psi" type="revolute">
    <parent link="rope_5"/>
    <child link="rope_6Psi_link"/>
    <origin xyz="0 0 -0.2"/>
    <axis xyz="0 0 1"/>
    <dynamics damping="0.05" friction="0.05"/>
    <limit effort="1000" lower="-0.196349540849" upper="0.196349540849" velocity="300"/>
  </joint>
  <link name="rope_6Psi_link">
    <inertial>
      <mass value="0.1"/>
      <inertia ixx="0.1" ixy="0.0" ixz="0.0" iyy="0.1" iyz="0.0" izz="0.1"/>
    </inertial>
  </link>
  <joint name="rope6Psi_to_rope6Theta" type="revolute">
    <parent link="rope_6Psi_link"/>
    <child link="rope_6Theta_link"/>
    <axis xyz="0 1 0"/>
    <dynamics damping="0.05" friction="0.05"/>
    <limit effort="1000" lower="-1.57079632679" upper="1.57079632679" velocity="300"/>
  </joint>
  <link name="rope_6Theta_link">
    <inertial>
      <mass value="0.1"/>
      <inertia ixx="0.1" ixy="0.0" ixz="0.0" iyy="0.1" iyz="0.0" izz="0.1"/>
    </inertial>
  </link>
  <joint name="rope6Theta_to_rope6" type="revolute">
    <parent link="rope_6Theta_link"/>
    <child link="rope_6"/>
    <axis xyz="1 0 0"/>
    <dynamics damping="0.05" friction="0.05"/>
    <limit effort="1000" lower="-1.57079632679" upper="1.57079632679" velocity="300"/>
  </joint>
  <joint name="rope6_to_rope7Psi" type="revolute">
    <parent link="rope_6"/>
    <child link="rope_7Psi_link"/>
    <origin xyz="0 0 -0.2"/>
    <axis xyz="0 0 1"/>
    <dynamics damping="0.05" friction="0.05"/>
    <limit effort="1000" lower="-0.196349540849" upper="0.196349540849" velocity="300"/>
  </joint>
  <link name="rope_7Psi_link">
    <inertial>
      <mass value="0.1"/>
      <inertia ixx="0.1" ixy="0.0" ixz="0.0" iyy="0.1" iyz="0.0" izz="0.1"/>
    </inertial>
  </link>
  <joint name="rope7Psi_to_rope6Theta" type="revolute">
    <parent link="rope_7Psi_link"/>
    <child link="rope_7Theta_link"/>
    <axis xyz="0 1 0"/>
    <dynamics damping="0.05" friction="0.05"/>
    <limit effort="1000" lower="-1.57079632679" upper="1.57079632679" velocity="300"/>
  </joint>
  <link name="rope_7Theta_link">
    <inertial>
      <mass value="0.1"/>
      <inertia ixx="0.1" ixy="0.0" ixz="0.0" iyy="0.1" iyz="0.0" izz="0.1"/>
    </inertial>
  </link>
  <joint name="rope7Theta_to_rope7" type="revolute">
    <parent link="rope_7Theta_link"/>
    <child link="rope_7"/>
    <axis xyz="1 0 0"/>
    <dynamics damping="0.05" friction="0.05"/>
    <limit effort="1000" lower="-1.57079632679" upper="1.57079632679" velocity="300"/>
  </joint>
  <joint name="rope7_to_load" type="revolute">
    <parent link="rope_7"/>
    <child link="load"/>
    <origin xyz="0 0 -0.2"/>
    <axis xyz="0 1 0"/>
    <dynamics damping="0.05" friction="0.05"/>
    <limit effort="1000" lower="-1.57079632679" upper="1.57079632679" velocity="300"/>
  </joint>
  <gazebo reference="rope_1">
    <material>Gazebo/Blue</material>
  </gazebo>
  <gazebo reference="rope_2">
    <material>Gazebo/Green</material>
  </gazebo>
  <gazebo reference="rope_3">
    <material>Gazebo/Blue</material>
  </gazebo>
  <gazebo reference="rope_4">
    <material>Gazebo/Green</material>
  </gazebo>
  <gazebo reference="rope_5">
    <material>Gazebo/Blue</material>
  </gazebo>
  <gazebo reference="rope_6">
    <material>Gazebo/Green</material>
  </gazebo>
  <gazebo reference="rope_7">
    <material>Gazebo/Blue</material>
  </gazebo>
  <gazebo reference="load">
    <material>Gazebo/Red</material>
  </gazebo>
  <!--
		<gazebo reference="rope_1">
			<mu1>0.01</mu1>
			<mu2>0.01</mu2>
		</gazebo>

		<gazebo reference="rope_2Psi_link">
			<mu1>0.01</mu1>
			<mu2>0.01</mu2>
		</gazebo>

		<gazebo reference="rope_2Theta_link">
			<mu1>0.01</mu1>
			<mu2>0.01</mu2>
		</gazebo>

		<gazebo reference="rope_3Psi_link">
			<mu1>0.01</mu1>
			<mu2>0.01</mu2>
		</gazebo>

		<gazebo reference="rope_3Theta_link">
			<mu1>0.01</mu1>
			<mu2>0.01</mu2>
		</gazebo>

		<gazebo reference="rope_4Psi_link">
			<mu1>0.01</mu1>
			<mu2>0.01</mu2>
		</gazebo> -->
  <!--
		<gazebo reference="rope2Theta_to_rope1">
			<implicitSpringDamper>0.7</implicitSpringDamper>
		</gazebo>

		<gazebo reference="rope4Theta_to_rope4">
			<implicitSpringDamper>0.7</implicitSpringDamper>
		</gazebo>

		<gazebo reference="rope3_to_rope4Psi">
			<implicitSpringDamper>0.7</implicitSpringDamper>
		</gazebo>-->
</robot>

<?xml version="1.0" ?>
<!-- =================================================================================== -->
<!-- |    This document was autogenerated by xacro from myrobot1.xacro                 | -->
<!-- |    EDITING THIS FILE BY HAND IS NOT RECOMMENDED                                 | -->
<!-- =================================================================================== -->
<robot name="myrobot" xmlns:xacro="http://www.ros.org/wiki/xacro">
  <link name="world"/>
  <link name="base_link">
    <visual>
      <geometry>
        <box size="0.5 1.5 0.5"/>
      </geometry>
    </visual>
    <collision>
      <geometry>
        <box size="0.5 1.5 0.5"/>
      </geometry>
      <origin rpy="0 0 0" xyz="0 0 3.0"/>
    </collision>
    <inertial>
      <mass value="0.005"/>
      <inertia ixx="0.005" ixy="0.0" ixz="0.0" iyy="0.005" iyz="0.0" izz="0.005"/>
      <origin rpy="0 0 0" xyz="0 0 3.0"/>
    </inertial>
  </link>
  <link name="leg1">
    <visual>
      <geometry>
        <box size="0.5 0.25  3.25"/>
      </geometry>
      <origin rpy="0 0 0" xyz="0 0 -1.5"/>
    </visual>
    <collision>
      <geometry>
        <box size="0.5 0.25  3.25"/>
      </geometry>
      <origin rpy="0 0 0" xyz="0 0 -1.5"/>
    </collision>
    <inertial>
      <mass value="100"/>
      <inertia ixx="100" ixy="0.0" ixz="0.0" iyy="100" iyz="0.0" izz="100"/>
      <origin rpy="0 0 0" xyz="0 1.5 -1.5"/>
    </inertial>
  </link>
  <link name="leg2">
    <visual>
      <geometry>
        <box size="0.5 -0.25  3.25"/>
      </geometry>
      <origin rpy="0 0 0" xyz="0 0 -1.5"/>
    </visual>
    <collision>
      <geometry>
        <box size="0.5 -0.25 3.25"/>
      </geometry>
      <origin rpy="0 0 0" xyz="0 0 1.5"/>
    </collision>
    <inertial>
      <mass value="100"/>
      <inertia ixx="100" ixy="0.0" ixz="0.0" iyy="100" iyz="0.0" izz="100"/>
      <origin rpy="0 0 0" xyz="0 -1.5 -1.5"/>
    </inertial>
  </link>
  <link name="rope_1">
    <visual>
      <geometry>
        <cylinder length="0.1" radius="0.004"/>
      </geometry>
      <origin rpy="0.0 0.0 0.0" xyz="0 0 -0.05"/>
    </visual>
    <collision>
      <geometry>
        <cylinder length="0.1" radius="0.004"/>
      </geometry>
      <origin rpy="0.0 0.0 0.0" xyz="0 0 -0.05"/>
    </collision>
    <inertial>
      <mass value="0.1"/>
      <inertia ixx="0.01" ixy="0.0" ixz="0.0" iyy="0.01" iyz="0.0" izz="0.02"/>
      <origin rpy="0.0 0.0 0.0" xyz="0 0 -0.05"/>
    </inertial>
  </link>
  <link name="rope_2">
    <visual>
      <geometry>
        <cylinder length="0.1" radius="0.004"/>
      </geometry>
      <origin rpy="0.0 0.0 0.0" xyz="0 0 -0.05"/>
    </visual>
    <collision>
      <geometry>
        <cylinder length="0.1" radius="0.004"/>
      </geometry>
      <origin rpy="0.0 0.0 0.0" xyz="0 0 -0.05"/>
    </collision>
    <inertial>
      <mass value="0.1"/>
      <inertia ixx="0.01" ixy="0.0" ixz="0.0" iyy="0.01" iyz="0.0" izz="0.02"/>
      <origin rpy="0.0 0.0 0.0" xyz="0 0 -0.05"/>
    </inertial>
  </link>
  <link name="rope_3">
    <visual>
      <geometry>
        <cylinder length="0.1" radius="0.004"/>
      </geometry>
      <origin rpy="0.0 0.0 0.0" xyz="0 0 -0.05"/>
    </visual>
    <collision>
      <geometry>
        <cylinder length="0.1" radius="0.004"/>
      </geometry>
      <origin rpy="0.0 0.0 0.0" xyz="0 0 -0.05"/>
    </collision>
    <inertial>
      <mass value="0.1"/>
      <inertia ixx="0.01" ixy="0.0" ixz="0.0" iyy="0.01" iyz="0.0" izz="0.02"/>
      <origin rpy="0.0 0.0 0.0" xyz="0 0 -0.05"/>
    </inertial>
  </link>
  <link name="rope_4">
    <visual>
      <geometry>
        <cylinder length="0.1" radius="0.004"/>
      </geometry>
      <origin rpy="0.0 0.0 0.0" xyz="0 0 -0.05"/>
    </visual>
    <collision>
      <geometry>
        <cylinder length="0.1" radius="0.004"/>
      </geometry>
      <origin rpy="0.0 0.0 0.0" xyz="0 0 -0.05"/>
    </collision>
    <inertial>
      <mass value="0.1"/>
      <inertia ixx="0.01" ixy="0.0" ixz="0.0" iyy="0.01" iyz="0.0" izz="0.02"/>
      <origin rpy="0.0 0.0 0.0" xyz="0 0 -0.05"/>
    </inertial>
  </link>
  <link name="rope_5">
    <visual>
      <geometry>
        <cylinder length="0.1" radius="0.004"/>
      </geometry>
      <origin rpy="0.0 0.0 0.0" xyz="0 0 -0.05"/>
    </visual>
    <collision>
      <geometry>
        <cylinder length="0.1" radius="0.004"/>
      </geometry>
      <origin rpy="0.0 0.0 0.0" xyz="0 0 -0.05"/>
    </collision>
    <inertial>
      <mass value="0.1"/>
      <inertia ixx="0.01" ixy="0.0" ixz="0.0" iyy="0.01" iyz="0.0" izz="0.02"/>
      <origin rpy="0.0 0.0 0.0" xyz="0 0 -0.05"/>
    </inertial>
  </link>
  <link name="rope_6">
    <visual>
      <geometry>
        <cylinder length="0.1" radius="0.004"/>
      </geometry>
      <origin rpy="0.0 0.0 0.0" xyz="0 0 -0.05"/>
    </visual>
    <collision>
      <geometry>
        <cylinder length="0.1" radius="0.004"/>
      </geometry>
      <origin rpy="0.0 0.0 0.0" xyz="0 0 -0.05"/>
    </collision>
    <inertial>
      <mass value="0.1"/>
      <inertia ixx="0.01" ixy="0.0" ixz="0.0" iyy="0.01" iyz="0.0" izz="0.02"/>
      <origin rpy="0.0 0.0 0.0" xyz="0 0 -0.05"/>
    </inertial>
  </link>
  <link name="rope_7">
    <visual>
      <geometry>
        <cylinder length="0.1" radius="0.004"/>
      </geometry>
      <origin rpy="0.0 0.0 0.0" xyz="0 0 -0.05"/>
    </visual>
    <collision>
      <geometry>
        <cylinder length="0.1" radius="0.004"/>
      </geometry>
      <origin rpy="0.0 0.0 0.0" xyz="0 0 -0.05"/>
    </collision>
    <inertial>
      <mass value="0.1"/>
      <inertia ixx="0.01" ixy="0.0" ixz="0.0" iyy="0.01" iyz="0.0" izz="0.02"/>
      <origin rpy="0.0 0.0 0.0" xyz="0 0 -0.05"/>
    </inertial>
  </link>
  <link name="rope_8">
    <visual>
      <geometry>
        <cylinder length="0.1" radius="0.004"/>
      </geometry>
      <origin rpy="0.0 0.0 0.0" xyz="0 0 -0.05"/>
    </visual>
    <collision>
      <geometry>
        <cylinder length="0.1" radius="0.004"/>
      </geometry>
      <origin rpy="0.0 0.0 0.0" xyz="0 0 -0.05"/>
    </collision>
    <inertial>
      <mass value="0.1"/>
      <inertia ixx="0.01" ixy="0.0" ixz="0.0" iyy="0.01" iyz="0.0" izz="0.02"/>
      <origin rpy="0.0 0.0 0.0" xyz="0 0 -0.05"/>
    </inertial>
  </link>
  <link name="rope_9">
    <visual>
      <geometry>
        <cylinder length="0.1" radius="0.004"/>
      </geometry>
      <origin rpy="0.0 0.0 0.0" xyz="0 0 -0.05"/>
    </visual>
    <collision>
      <geometry>
        <cylinder length="0.1" radius="0.004"/>
      </geometry>
      <origin rpy="0.0 0.0 0.0" xyz="0 0 -0.05"/>
    </collision>
    <inertial>
      <mass value="0.1"/>
      <inertia ixx="0.01" ixy="0.0" ixz="0.0" iyy="0.01" iyz="0.0" izz="0.02"/>
      <origin rpy="0.0 0.0 0.0" xyz="0 0 -0.05"/>
    </inertial>
  </link>
  <link name="rope_10">
    <visual>
      <geometry>
        <cylinder length="0.1" radius="0.004"/>
      </geometry>
      <origin rpy="0.0 0.0 0.0" xyz="0 0 -0.05"/>
    </visual>
    <collision>
      <geometry>
        <cylinder length="0.1" radius="0.004"/>
      </geometry>
      <origin rpy="0.0 0.0 0.0" xyz="0 0 -0.05"/>
    </collision>
    <inertial>
      <mass value="0.1"/>
      <inertia ixx="0.01" ixy="0.0" ixz="0.0" iyy="0.01" iyz="0.0" izz="0.02"/>
      <origin rpy="0.0 0.0 0.0" xyz="0 0 -0.05"/>
    </inertial>
  </link>
  <link name="load">
    <visual>
      <geometry>
        <sphere radius="0.101"/>
      </geometry>
      <origin rpy="0.0 0.0 0.0" xyz="0 0 -0.101"/>
    </visual>
    <collision>
      <geometry>
        <sphere radius="0.101"/>
      </geometry>
      <origin rpy="0.0 0.0 0.0" xyz="0 0 -0.101"/>
    </collision>
    <inertial>
      <mass value="2.0"/>
      <inertia ixx="0.0" ixy="0.0" ixz="0.0" iyy="0.0" iyz="0.0" izz="0.0"/>
      <origin rpy="0.0 0.0 0.0" xyz="0 0 -0.101"/>
    </inertial>
  </link>
  <joint name="world_base_link" type="fixed">
    <parent link="world"/>
    <child link="base_link"/>
    <origin rpy="0.0 0.0 0.0" xyz="0 0 3.0"/>
  </joint>
  <joint name="leg1_base_link" type="fixed">
    <parent link="base_link"/>
    <child link="leg1"/>
    <origin xyz="0 0.875 0.125"/>
  </joint>
  <joint name="leg2_base_link" type="fixed">
    <parent link="base_link"/>
    <child link="leg2"/>
    <origin xyz="0 -0.875 0.125"/>
  </joint>
  <link name="rope1Theta">
    <inertial>
      <mass value="0.001"/>
      <inertia ixx="0.01" ixy="0.0" ixz="0.0" iyy="0.01" iyz="0.0" izz="0.01"/>
    </inertial>
  </link>
  <link name="rope1Psi">
    <inertial>
      <mass value="0.001"/>
      <inertia ixx="0.01" ixy="0.0" ixz="0.0" iyy="0.01" iyz="0.0" izz="0.01"/>
    </inertial>
  </link>
  <joint name="base_link_to_rope1Psi" type="revolute">
    <parent link="base_link"/>
    <child link="rope1Psi"/>
    <origin rpy="0.0 0.0 0.0" xyz="0 0 -0.25"/>
    <axis xyz="0 0 1"/>
    <dynamics damping="0.5" friction="0.02"/>
    <limit effort="1000" lower="-1.57079632679" upper="1.57079632679" velocity="300"/>
  </joint>
  <joint name="rope1Psi_to_rope1Theta" type="revolute">
    <parent link="rope1Psi"/>
    <child link="rope1Theta"/>
    <axis xyz="0 1 0"/>
    <dynamics damping="0.5" friction="0.02"/>
    <limit effort="1000" lower="-1.57079632679" upper="1.57079632679" velocity="300"/>
  </joint>
  <joint name="rope1Theta_to_rope_1" type="revolute">
    <parent link="rope1Theta"/>
    <child link="rope_1"/>
    <axis xyz="1 0 0"/>
    <dynamics damping="0.5" friction="0.02"/>
    <limit effort="1000" lower="-0.196349540849" upper="0.196349540849" velocity="300"/>
  </joint>
  <link name="rope2Theta">
    <inertial>
      <mass value="0.001"/>
      <inertia ixx="0.01" ixy="0.0" ixz="0.0" iyy="0.01" iyz="0.0" izz="0.01"/>
    </inertial>
  </link>
  <link name="rope2Psi">
    <inertial>
      <mass value="0.001"/>
      <inertia ixx="0.01" ixy="0.0" ixz="0.0" iyy="0.01" iyz="0.0" izz="0.01"/>
    </inertial>
  </link>
  <joint name="rope_1_to_rope2Psi" type="revolute">
    <parent link="rope_1"/>
    <child link="rope2Psi"/>
    <origin rpy="0.0 0.0 0.0" xyz="0 0 -0.1"/>
    <axis xyz="0 0 1"/>
    <dynamics damping="0.5" friction="0.02"/>
    <limit effort="1000" lower="-1.57079632679" upper="1.57079632679" velocity="300"/>
  </joint>
  <joint name="rope2Psi_to_rope2Theta" type="revolute">
    <parent link="rope2Psi"/>
    <child link="rope2Theta"/>
    <axis xyz="0 1 0"/>
    <dynamics damping="0.5" friction="0.02"/>
    <limit effort="1000" lower="-1.57079632679" upper="1.57079632679" velocity="300"/>
  </joint>
  <joint name="rope2Theta_to_rope_2" type="revolute">
    <parent link="rope2Theta"/>
    <child link="rope_2"/>
    <axis xyz="1 0 0"/>
    <dynamics damping="0.5" friction="0.02"/>
    <limit effort="1000" lower="-0.196349540849" upper="0.196349540849" velocity="300"/>
  </joint>
  <link name="rope3Theta">
    <inertial>
      <mass value="0.001"/>
      <inertia ixx="0.01" ixy="0.0" ixz="0.0" iyy="0.01" iyz="0.0" izz="0.01"/>
    </inertial>
  </link>
  <link name="rope3Psi">
    <inertial>
      <mass value="0.001"/>
      <inertia ixx="0.01" ixy="0.0" ixz="0.0" iyy="0.01" iyz="0.0" izz="0.01"/>
    </inertial>
  </link>
  <joint name="rope_2_to_rope3Psi" type="revolute">
    <parent link="rope_2"/>
    <child link="rope3Psi"/>
    <origin rpy="0.0 0.0 0.0" xyz="0 0 -0.1"/>
    <axis xyz="0 0 1"/>
    <dynamics damping="0.5" friction="0.02"/>
    <limit effort="1000" lower="-1.57079632679" upper="1.57079632679" velocity="300"/>
  </joint>
  <joint name="rope3Psi_to_rope3Theta" type="revolute">
    <parent link="rope3Psi"/>
    <child link="rope3Theta"/>
    <axis xyz="0 1 0"/>
    <dynamics damping="0.5" friction="0.02"/>
    <limit effort="1000" lower="-1.57079632679" upper="1.57079632679" velocity="300"/>
  </joint>
  <joint name="rope3Theta_to_rope_3" type="revolute">
    <parent link="rope3Theta"/>
    <child link="rope_3"/>
    <axis xyz="1 0 0"/>
    <dynamics damping="0.5" friction="0.02"/>
    <limit effort="1000" lower="-0.196349540849" upper="0.196349540849" velocity="300"/>
  </joint>
  <link name="rope4Theta">
    <inertial>
      <mass value="0.001"/>
      <inertia ixx="0.01" ixy="0.0" ixz="0.0" iyy="0.01" iyz="0.0" izz="0.01"/>
    </inertial>
  </link>
  <link name="rope4Psi">
    <inertial>
      <mass value="0.001"/>
      <inertia ixx="0.01" ixy="0.0" ixz="0.0" iyy="0.01" iyz="0.0" izz="0.01"/>
    </inertial>
  </link>
  <joint name="rope_3_to_rope4Psi" type="revolute">
    <parent link="rope_3"/>
    <child link="rope4Psi"/>
    <origin rpy="0.0 0.0 0.0" xyz="0 0 -0.1"/>
    <axis xyz="0 0 1"/>
    <dynamics damping="0.5" friction="0.02"/>
    <limit effort="1000" lower="-1.57079632679" upper="1.57079632679" velocity="300"/>
  </joint>
  <joint name="rope4Psi_to_rope4Theta" type="revolute">
    <parent link="rope4Psi"/>
    <child link="rope4Theta"/>
    <axis xyz="0 1 0"/>
    <dynamics damping="0.5" friction="0.02"/>
    <limit effort="1000" lower="-1.57079632679" upper="1.57079632679" velocity="300"/>
  </joint>
  <joint name="rope4Theta_to_rope_4" type="revolute">
    <parent link="rope4Theta"/>
    <child link="rope_4"/>
    <axis xyz="1 0 0"/>
    <dynamics damping="0.5" friction="0.02"/>
    <limit effort="1000" lower="-0.196349540849" upper="0.196349540849" velocity="300"/>
  </joint>
  <link name="rope5Theta">
    <inertial>
      <mass value="0.001"/>
      <inertia ixx="0.01" ixy="0.0" ixz="0.0" iyy="0.01" iyz="0.0" izz="0.01"/>
    </inertial>
  </link>
  <link name="rope5Psi">
    <inertial>
      <mass value="0.001"/>
      <inertia ixx="0.01" ixy="0.0" ixz="0.0" iyy="0.01" iyz="0.0" izz="0.01"/>
    </inertial>
  </link>
  <joint name="rope_4_to_rope5Psi" type="revolute">
    <parent link="rope_4"/>
    <child link="rope5Psi"/>
    <origin rpy="0.0 0.0 0.0" xyz="0 0 -0.1"/>
    <axis xyz="0 0 1"/>
    <dynamics damping="0.5" friction="0.02"/>
    <limit effort="1000" lower="-1.57079632679" upper="1.57079632679" velocity="300"/>
  </joint>
  <joint name="rope5Psi_to_rope5Theta" type="revolute">
    <parent link="rope5Psi"/>
    <child link="rope5Theta"/>
    <axis xyz="0 1 0"/>
    <dynamics damping="0.5" friction="0.02"/>
    <limit effort="1000" lower="-1.57079632679" upper="1.57079632679" velocity="300"/>
  </joint>
  <joint name="rope5Theta_to_rope_5" type="revolute">
    <parent link="rope5Theta"/>
    <child link="rope_5"/>
    <axis xyz="1 0 0"/>
    <dynamics damping="0.5" friction="0.02"/>
    <limit effort="1000" lower="-0.196349540849" upper="0.196349540849" velocity="300"/>
  </joint>
  <link name="rope6Theta">
    <inertial>
      <mass value="0.001"/>
      <inertia ixx="0.01" ixy="0.0" ixz="0.0" iyy="0.01" iyz="0.0" izz="0.01"/>
    </inertial>
  </link>
  <link name="rope6Psi">
    <inertial>
      <mass value="0.001"/>
      <inertia ixx="0.01" ixy="0.0" ixz="0.0" iyy="0.01" iyz="0.0" izz="0.01"/>
    </inertial>
  </link>
  <joint name="rope_5_to_rope6Psi" type="revolute">
    <parent link="rope_5"/>
    <child link="rope6Psi"/>
    <origin rpy="0.0 0.0 0.0" xyz="0 0 -0.1"/>
    <axis xyz="0 0 1"/>
    <dynamics damping="0.5" friction="0.02"/>
    <limit effort="1000" lower="-1.57079632679" upper="1.57079632679" velocity="300"/>
  </joint>
  <joint name="rope6Psi_to_rope6Theta" type="revolute">
    <parent link="rope6Psi"/>
    <child link="rope6Theta"/>
    <axis xyz="0 1 0"/>
    <dynamics damping="0.5" friction="0.02"/>
    <limit effort="1000" lower="-1.57079632679" upper="1.57079632679" velocity="300"/>
  </joint>
  <joint name="rope6Theta_to_rope_6" type="revolute">
    <parent link="rope6Theta"/>
    <child link="rope_6"/>
    <axis xyz="1 0 0"/>
    <dynamics damping="0.5" friction="0.02"/>
    <limit effort="1000" lower="-0.196349540849" upper="0.196349540849" velocity="300"/>
  </joint>
  <link name="rope7Theta">
    <inertial>
      <mass value="0.001"/>
      <inertia ixx="0.01" ixy="0.0" ixz="0.0" iyy="0.01" iyz="0.0" izz="0.01"/>
    </inertial>
  </link>
  <link name="rope7Psi">
    <inertial>
      <mass value="0.001"/>
      <inertia ixx="0.01" ixy="0.0" ixz="0.0" iyy="0.01" iyz="0.0" izz="0.01"/>
    </inertial>
  </link>
  <joint name="rope_6_to_rope7Psi" type="revolute">
    <parent link="rope_6"/>
    <child link="rope7Psi"/>
    <origin rpy="0.0 0.0 0.0" xyz="0 0 -0.1"/>
    <axis xyz="0 0 1"/>
    <dynamics damping="0.5" friction="0.02"/>
    <limit effort="1000" lower="-1.57079632679" upper="1.57079632679" velocity="300"/>
  </joint>
  <joint name="rope7Psi_to_rope7Theta" type="revolute">
    <parent link="rope7Psi"/>
    <child link="rope7Theta"/>
    <axis xyz="0 1 0"/>
    <dynamics damping="0.5" friction="0.02"/>
    <limit effort="1000" lower="-1.57079632679" upper="1.57079632679" velocity="300"/>
  </joint>
  <joint name="rope7Theta_to_rope_7" type="revolute">
    <parent link="rope7Theta"/>
    <child link="rope_7"/>
    <axis xyz="1 0 0"/>
    <dynamics damping="0.5" friction="0.02"/>
    <limit effort="1000" lower="-0.196349540849" upper="0.196349540849" velocity="300"/>
  </joint>
  <link name="rope8Theta">
    <inertial>
      <mass value="0.001"/>
      <inertia ixx="0.01" ixy="0.0" ixz="0.0" iyy="0.01" iyz="0.0" izz="0.01"/>
    </inertial>
  </link>
  <link name="rope8Psi">
    <inertial>
      <mass value="0.001"/>
      <inertia ixx="0.01" ixy="0.0" ixz="0.0" iyy="0.01" iyz="0.0" izz="0.01"/>
    </inertial>
  </link>
  <joint name="rope_7_to_rope8Psi" type="revolute">
    <parent link="rope_7"/>
    <child link="rope8Psi"/>
    <origin rpy="0.0 0.0 0.0" xyz="0 0 -0.1"/>
    <axis xyz="0 0 1"/>
    <dynamics damping="0.5" friction="0.02"/>
    <limit effort="1000" lower="-1.57079632679" upper="1.57079632679" velocity="300"/>
  </joint>
  <joint name="rope8Psi_to_rope8Theta" type="revolute">
    <parent link="rope8Psi"/>
    <child link="rope8Theta"/>
    <axis xyz="0 1 0"/>
    <dynamics damping="0.5" friction="0.02"/>
    <limit effort="1000" lower="-1.57079632679" upper="1.57079632679" velocity="300"/>
  </joint>
  <joint name="rope8Theta_to_rope_8" type="revolute">
    <parent link="rope8Theta"/>
    <child link="rope_8"/>
    <axis xyz="1 0 0"/>
    <dynamics damping="0.5" friction="0.02"/>
    <limit effort="1000" lower="-0.196349540849" upper="0.196349540849" velocity="300"/>
  </joint>
  <link name="rope9Theta">
    <inertial>
      <mass value="0.001"/>
      <inertia ixx="0.01" ixy="0.0" ixz="0.0" iyy="0.01" iyz="0.0" izz="0.01"/>
    </inertial>
  </link>
  <link name="rope9Psi">
    <inertial>
      <mass value="0.001"/>
      <inertia ixx="0.01" ixy="0.0" ixz="0.0" iyy="0.01" iyz="0.0" izz="0.01"/>
    </inertial>
  </link>
  <joint name="rope_8_to_rope9Psi" type="revolute">
    <parent link="rope_8"/>
    <child link="rope9Psi"/>
    <origin rpy="0.0 0.0 0.0" xyz="0 0 -0.1"/>
    <axis xyz="0 0 1"/>
    <dynamics damping="0.5" friction="0.02"/>
    <limit effort="1000" lower="-1.57079632679" upper="1.57079632679" velocity="300"/>
  </joint>
  <joint name="rope9Psi_to_rope9Theta" type="revolute">
    <parent link="rope9Psi"/>
    <child link="rope9Theta"/>
    <axis xyz="0 1 0"/>
    <dynamics damping="0.5" friction="0.02"/>
    <limit effort="1000" lower="-1.57079632679" upper="1.57079632679" velocity="300"/>
  </joint>
  <joint name="rope9Theta_to_rope_9" type="revolute">
    <parent link="rope9Theta"/>
    <child link="rope_9"/>
    <axis xyz="1 0 0"/>
    <dynamics damping="0.5" friction="0.02"/>
    <limit effort="1000" lower="-0.196349540849" upper="0.196349540849" velocity="300"/>
  </joint>
  <link name="rope10Theta">
    <inertial>
      <mass value="0.001"/>
      <inertia ixx="0.01" ixy="0.0" ixz="0.0" iyy="0.01" iyz="0.0" izz="0.01"/>
    </inertial>
  </link>
  <link name="rope10Psi">
    <inertial>
      <mass value="0.001"/>
      <inertia ixx="0.01" ixy="0.0" ixz="0.0" iyy="0.01" iyz="0.0" izz="0.01"/>
    </inertial>
  </link>
  <joint name="rope_9_to_rope10Psi" type="revolute">
    <parent link="rope_9"/>
    <child link="rope10Psi"/>
    <origin rpy="0.0 0.0 0.0" xyz="0 0 -0.1"/>
    <axis xyz="0 0 1"/>
    <dynamics damping="0.5" friction="0.02"/>
    <limit effort="1000" lower="-1.57079632679" upper="1.57079632679" velocity="300"/>
  </joint>
  <joint name="rope10Psi_to_rope10Theta" type="revolute">
    <parent link="rope10Psi"/>
    <child link="rope10Theta"/>
    <axis xyz="0 1 0"/>
    <dynamics damping="0.5" friction="0.02"/>
    <limit effort="1000" lower="-1.57079632679" upper="1.57079632679" velocity="300"/>
  </joint>
  <joint name="rope10Theta_to_rope_10" type="revolute">
    <parent link="rope10Theta"/>
    <child link="rope_10"/>
    <axis xyz="1 0 0"/>
    <dynamics damping="0.5" friction="0.02"/>
    <limit effort="1000" lower="-0.196349540849" upper="0.196349540849" velocity="300"/>
  </joint>
  <link name="rope11Theta">
    <inertial>
      <mass value="0.001"/>
      <inertia ixx="0.01" ixy="0.0" ixz="0.0" iyy="0.01" iyz="0.0" izz="0.01"/>
    </inertial>
  </link>
  <link name="rope11Psi">
    <inertial>
      <mass value="0.001"/>
      <inertia ixx="0.01" ixy="0.0" ixz="0.0" iyy="0.01" iyz="0.0" izz="0.01"/>
    </inertial>
  </link>
  <joint name="rope_10_to_rope11Psi" type="revolute">
    <parent link="rope_10"/>
    <child link="rope11Psi"/>
    <origin rpy="0.0 0.0 0.0" xyz="0 0 -0.1"/>
    <axis xyz="0 0 1"/>
    <dynamics damping="0.5" friction="0.02"/>
    <limit effort="1000" lower="-1.57079632679" upper="1.57079632679" velocity="300"/>
  </joint>
  <joint name="rope11Psi_to_rope11Theta" type="revolute">
    <parent link="rope11Psi"/>
    <child link="rope11Theta"/>
    <axis xyz="0 1 0"/>
    <dynamics damping="0.5" friction="0.02"/>
    <limit effort="1000" lower="-1.57079632679" upper="1.57079632679" velocity="300"/>
  </joint>
  <joint name="rope11Theta_to_load" type="revolute">
    <parent link="rope11Theta"/>
    <child link="load"/>
    <axis xyz="1 0 0"/>
    <dynamics damping="0.5" friction="0.02"/>
    <limit effort="1000" lower="-0.196349540849" upper="0.196349540849" velocity="300"/>
  </joint>
  <gazebo reference="rope_1">
    <material>Gazebo/Blue</material>
  </gazebo>
  <gazebo reference="rope_2">
    <material>Gazebo/Green</material>
  </gazebo>
  <gazebo reference="rope_3">
    <material>Gazebo/Blue</material>
  </gazebo>
  <gazebo reference="rope_4">
    <material>Gazebo/Green</material>
  </gazebo>
  <gazebo reference="rope_5">
    <material>Gazebo/Blue</material>
  </gazebo>
  <gazebo reference="rope_6">
    <material>Gazebo/Green</material>
  </gazebo>
  <gazebo reference="rope_7">
    <material>Gazebo/Blue</material>
  </gazebo>
  <gazebo reference="rope_8">
    <material>Gazebo/Green</material>
  </gazebo>
  <gazebo reference="rope_9">
    <material>Gazebo/Blue</material>
  </gazebo>
  <gazebo reference="rope_10">
    <material>Gazebo/Green</material>
  </gazebo>
  <gazebo reference="load">
    <material>Gazebo/Red</material>
  </gazebo>
</robot>

